[32m2024-11-26 17:07:52 +0100[0m - dagster - [34mDEBUG[0m - tech_sentiment_job - dc0dfdc2-35e0-4b69-848c-2ecd65b15929 - 554453 - LOGS_CAPTURED - Started capturing logs in process (pid: 554453).
[32m2024-11-26 17:07:52 +0100[0m - dagster - [34mDEBUG[0m - tech_sentiment_job - dc0dfdc2-35e0-4b69-848c-2ecd65b15929 - 554453 - load_and_prepare_sentiment2_data - STEP_START - Started execution of step "load_and_prepare_sentiment2_data".
[32m2024-11-26 17:07:56 +0100[0m - dagster - [34mERROR[0m - [31mtech_sentiment_job - dc0dfdc2-35e0-4b69-848c-2ecd65b15929 - 554453 - load_and_prepare_sentiment2_data - STEP_FAILURE - Execution of step "load_and_prepare_sentiment2_data" failed.

dagster._core.errors.DagsterExecutionStepExecutionError: Error occurred while executing op "load_and_prepare_sentiment2_data"::

AttributeError: module 'quickstart_etl.assets.constants' has no attribute 'OUTPUT_PATH'

Stack Trace:
  File "/home/urban/anaconda3/envs/myenv/lib/python3.8/site-packages/dagster/_core/execution/plan/utils.py", line 54, in op_execution_error_boundary
    yield
  File "/home/urban/anaconda3/envs/myenv/lib/python3.8/site-packages/dagster/_utils/__init__.py", line 482, in iterate_with_context
    next_output = next(iterator)
  File "/home/urban/anaconda3/envs/myenv/lib/python3.8/site-packages/dagster/_core/execution/plan/compute_generator.py", line 140, in _coerce_op_compute_fn_to_iterator
    result = invoke_compute_fn(
  File "/home/urban/anaconda3/envs/myenv/lib/python3.8/site-packages/dagster/_core/execution/plan/compute_generator.py", line 128, in invoke_compute_fn
    return fn(context, **args_to_pass) if context_arg_provided else fn(**args_to_pass)
  File "/home/urban/Projekty/dagster2/my-dagster-project/quickstart_etl/assets/sentiment.py", line 140, in load_and_prepare_sentiment2_data
    output_path = os.path.join(constants.OUTPUT_PATH, "filtered_data.csv")
[0m
